Workbook

Sheet Summary
A1: Tamil Nadu Sports Facilities — Consolidated & De-duplicated
A3: Source files merged:
A4: 1. Tamil_Nadu_38_Districts_New_data.xlsx
A5: 2. TamilNadu_Sports_Data__1_.xlsx
A7: S.No | B7: District | C7: Unique Records (after de-dup) | D7: Leads | E7: Rejection
A8: 1 | B8: Ariyalur | C8: =COUNTA(Ariyalur!A2:A100000) -> 392
A9: 2 | B9: Chengalpattu | C9: =COUNTA(Chengalpattu!A2:A100000) -> 380
A10: 3 | B10: Chennai | C10: =COUNTA(Chennai!A2:A100000) -> 578
A11: 4 | B11: Coimbatore | C11: =COUNTA(Coimbatore!A2:A100000) -> 491
A12: 5 | B12: Cuddalore | C12: =COUNTA(Cuddalore!A2:A99999) -> 364
A13: 6 | B13: Dharmapuri | C13: =COUNTA(Dharmapuri!A2:A100000) -> 274
A14: 7 | B14: Dindigul | C14: =COUNTA(Dindigul!A2:A99996) -> 371 | E14: 75
A15: 8 | B15: Erode | C15: =COUNTA(Erode!A2:A100000) -> 232 | D15: 7 | E15: 117
A16: 9 | B16: Kallakurichi | C16: =COUNTA(Kallakurichi!A2:A100001) -> 351 | D16: 3
A17: 10 | B17: Kanchipuram | C17: =COUNTA(Kanchipuram!A2:A100000) -> 218
A18: 11 | B18: Kanniyakumari | C18: =COUNTA(Kanniyakumari!A1:A99997) -> 401
A19: 12 | B19: Karur | C19: =COUNTA(Karur!A2:A100000) -> 362
A20: 13 | B20: Krishnagiri | C20: =COUNTA(Krishnagiri!A2:A100000) -> 384
A21: 14 | B21: Madurai | C21: =COUNTA(Madurai!A2:A100000) -> 490
A22: 15 | B22: Mayiladuthurai | C22: =COUNTA(Mayiladuthurai!A2:A100000) -> 368
A23: 16 | B23: Nagapattinam | C23: =COUNTA(Nagapattinam!A2:A100000) -> 370
A24: 17 | B24: Namakkal | C24: =COUNTA(Namakkal!A2:A100000) -> 225
A25: 18 | B25: Nilgiris | C25: =COUNTA(Nilgiris!A2:A100000) -> 145
A26: 19 | B26: Perambalur | C26: =COUNTA(Perambalur!A2:A100000) -> 150
A27: 20 | B27: Pudukkottai | C27: =COUNTA(Pudukkottai!A2:A100000) -> 148
A28: 21 | B28: Ramanathapuram | C28: =COUNTA(Ramanathapuram!A2:A99999) -> 207
A29: 22 | B29: Ranipet | C29: =COUNTA(Ranipet!A2:A99999) -> 234
A30: 23 | B30: Salem | C30: =COUNTA(Salem!A2:A100000) -> 383
A31: 24 | B31: Sivagangai | C31: =COUNTA(Sivagangai!A2:A100000) -> 126 | E31: 49
A32: 25 | B32: Tenkasi | C32: =COUNTA(Tenkasi!A2:A100000) -> 137
A33: 26 | B33: Thanjavur | C33: =COUNTA(Thanjavur!A2:A100000) -> 179
A34: 27 | B34: Theni | C34: =COUNTA(Theni!A2:A100000) -> 169
A35: 28 | B35: Thoothukudi | C35: =COUNTA(Thoothukudi!A2:A100000) -> 214
A36: 29 | B36: Tiruchirappalli | C36: =COUNTA(Tiruchirappalli!A2:A100000) -> 265
A37: 30 | B37: Tirunelveli | C37: =COUNTA(Tirunelveli!A2:A100000) -> 221
A38: 31 | B38: Tirupathur | C38: =COUNTA(Tirupathur!A2:A100000) -> 180
A39: 32 | B39: Tiruppur | C39: =COUNTA(Tiruppur!A2:A100000) -> 218
A40: 33 | B40: Tiruvallur | C40: =COUNTA(Tiruvallur!A2:A100000) -> 172
A41: 34 | B41: Tiruvannamalai | C41: =COUNTA(Tiruvannamalai!A2:A100000) -> 147
A42: 35 | B42: Tiruvarur | C42: =COUNTA(Tiruvarur!A2:A100000) -> 139
...

Sheet Sheet1

Sheet Ariyalur
A1: S.No | B1: District | C1: Category | D1: Facility Name | E1: Address | F1: Phone | G1: Source | H1: Maps Link | I1: Origin File
A2: 1 | B2: Ariyalur | C2: Academy | D2: Chola Sports Academy | E2: Jayankondam, Ariyalur-621802, Tamil Nadu | G2: old data | I2: TamilNadu_Sports_Data__1_.xlsx
A3: 2 | B3: Ariyalur | C3: Academy | D3: Hit Sports Academy | E3: Sevaga Street, Jayankondacholapuram, Ariyalur-621802, Tamil Nadu | F3: 7947112046 | G3: 25/03/2026 | I3: TamilNadu_Sports_Data__1_.xlsx
A4: 3 | B4: Ariyalur | C4: Academy | D4: Independent Cricket Academy | E4: 3/90, Colonystreet, Sundipallam, Jayankondam, Kundaveli, Ariyalur-612903, Tamil Nadu | F4: 7947128047 | G4: 25/03/2026 | I4: TamilNadu_Sports_Data__1_.xlsx
A5: 4 | B5: Ariyalur | C5: Academy | D5: Jai Ajay Badminton Academy | E5: Kovil St, Varadarajanpettai, Varadarajampettai, Ariyalur-621805, Tamil Nadu | F5: 7947424857 | G5: 25/03/2026 | I5: TamilNadu_Sports_Data__1_.xlsx
A6: 5 | B6: Ariyalur | C6: Academy | D6: Metro Indoor Sports Academy | E6: Annai Mahal, Permbalur - Ariyalur Rd, opposite 4 road, Min Nagar, Perambalur, Tamil Nadu 621220 | F6: 91598 45585 | G6: 25/03/2026 | I6: TamilNadu_Sports_Data__1_.xlsx
A7: 6 | B7: Ariyalur | C7: Academy | D7: Rook Squares Chess Academy | E7: No.43/12 A 1, Near Government Arts College, Rajaji Nagar, College Road, North, Ariyalur-621713, Tamil Nadu | F7: 8128412375 | G7: 25/03/2026 | I7: TamilNadu_Sports_Data__1_.xlsx
A8: 7 | B8: Ariyalur | C8: Academy | D8: Rook Squares Chess Academy & Chess Coaching Ariyalur District | E8: No43/12 A1, Near Government Arts College, Rajaji Nagar College Road, North, Ariyalur-621713, Tamil Nadu | F8: 7383489272 | G8: 25/03/2026 | I8: TamilNadu_Sports_Data__1_.xlsx
A9: 8 | B9: Ariyalur | C9: Academy | D9: SKY GOAL MARTIAL ARTS ACADEMY | E9: Pound St, opposite IcIcI ATM, near CSI Hr.sec School, MIN Nagar, Ariyalur, Tamil Nadu 621704 | F9: 90479 50482 | G9: 25/03/2026 | I9: TamilNadu_Sports_Data__1_.xlsx
A10: 9 | B10: Ariyalur | C10: Academy | D10: Thirumurugan Sports & Arts Academy | E10: Anandam Nagar, Jayankondam, Sendurai Road, Jayankondam, Ariyalur-621802, Tamil Nadu | F10: 7947124693 | G10: 25/03/2026 | I10: TamilNadu_Sports_Data__1_.xlsx
A11: 10 | B11: Ariyalur | C11: Athletic Track | D11: Ariyalur Thathanur Running Stadium | E11: Thathanur Main Road, near Thathanur Bazaar, Ariyalur District, Tamil Nadu 621749 | F11: +91 97895 91328 | G11: Google Maps | H11: https://maps.google.com/?q=Ariyalur+Thathanur+Running+Stadium+Ariyalur | I11: Tamil_Nadu_38_Districts_New_data.xlsx
A12: 11 | B12: Ariyalur | C12: Athletic Track | D12: Champion Sendurai Running Stadium | E12: Sendurai Main Road, near Sendurai Bazaar, Ariyalur District, Tamil Nadu 621813 | F12: +91 98430 73607 | G12: Justdial | H12: https://maps.google.com/?q=Champion+Sendurai+Running+Stadium+Ariyalur | I12: Tamil_Nadu_38_Districts_New_data.xlsx
A13: 12 | B13: Ariyalur | C13: Athletic Track | D13: Classic Keelapalur Running Stadium | E13: Keelapalur Main Road, near Keelapalur Bazaar, Ariyalur District, Tamil Nadu 621821 | F13: +91 99448 90075 | G13: Justdial | H13: https://maps.google.com/?q=Classic+Keelapalur+Running+Stadium+Ariyalur | I13: Tamil_Nadu_38_Districts_New_data.xlsx
A14: 13 | B14: Ariyalur | C14: Athletic Track | D14: District Thathanur Running Stadium | E14: Thathanur Main Road, near Thathanur Bazaar, Ariyalur District, Tamil Nadu 621718 | F14: +91 98430 78275 | G14: Justdial | H14: https://maps.google.com/?q=District+Thathanur+Running+Stadium+Ariyalur | I14: Tamil_Nadu_38_Districts_New_data.xlsx
A15: 14 | B15: Ariyalur | C15: Athletic Track | D15: Metro Kulumur Athletic Track Ground | E15: Kulumur Main Road, near Kulumur Bazaar, Ariyalur District, Tamil Nadu 621743 | F15: +91 97895 66209 | G15: Google Maps | H15: https://maps.google.com/?q=Metro+Kulumur+Athletic+Track+Ground+Ariyalur | I15: Tamil_Nadu_38_Districts_New_data.xlsx
A16: 15 | B16: Ariyalur | C16: Athletic Track | D16: Royal Kulumur Athletic Track Ground | E16: Kulumur Main Road, near Kulumur Bazaar, Ariyalur District, Tamil Nadu 621791 | F16: +91 98421 23509 | G16: Google Maps | H16: https://maps.google.com/?q=Royal+Kulumur+Athletic+Track+Ground+Ariyalur | I16: Tamil_Nadu_38_Districts_New_data.xlsx
A17: 16 | B17: Ariyalur | C17: Athletic Track | D17: Star Vilandhai Athletic Track Ground | E17: Vilandhai Main Road, near Vilandhai Bazaar, Ariyalur District, Tamil Nadu 621817 | F17: +91 97895 30289 | G17: Justdial | H17: https://maps.google.com/?q=Star+Vilandhai+Athletic+Track+Ground+Ariyalur | I17: Tamil_Nadu_38_Districts_New_data.xlsx
A18: 17 | B18: Ariyalur | C18: Athletic Track | D18: Summit Kulumur Athletic Track Ground | E18: Kulumur Main Road, near Kulumur Bazaar, Ariyalur District, Tamil Nadu 621769 | F18: +91 99448 14006 | G18: Justdial | H18: https://maps.google.com/?q=Summit+Kulumur+Athletic+Track+Ground+Ariyalur | I18: Tamil_Nadu_38_Districts_New_data.xlsx
A19: 18 | B19: Ariyalur | C19: Athletic Track | D19: Summit Vanjinapuram Running Stadium | E19: Vanjinapuram Main Road, near Vanjinapuram Bazaar, Ariyalur District, Tamil Nadu 621769 | F19: +91 96299 60152 | G19: Justdial | H19: https://maps.google.com/?q=Summit+Vanjinapuram+Running+Stadium+Ariyalur | I19: Tamil_Nadu_38_Districts_New_data.xlsx
A20: 19 | B20: Ariyalur | C20: Athletic Track | D20: Titan Vilandhai Running Stadium | E20: Vilandhai Main Road, near Vilandhai Bazaar, Ariyalur District, Tamil Nadu 621702 | F20: +91 96299 34273 | G20: Google Maps | H20: https://maps.google.com/?q=Titan+Vilandhai+Running+Stadium+Ariyalur | I20: Tamil_Nadu_38_Districts_New_data.xlsx
A21: 20 | B21: Ariyalur | C21: Athletic Track | D21: United Meensurutti Running Stadium | E21: Meensurutti Main Road, near Meensurutti Bazaar, Ariyalur District, Tamil Nadu 621822 | F21: 079044 79184 | G21: Google Maps | H21: https://maps.google.com/?q=United+Meensurutti+Running+Stadium+Ariyalur | I21: Tamil_Nadu_38_Districts_New_data.xlsx
A22: 21 | B22: Ariyalur | C22: Athletic Track | D22: Vee Kallankurichi Athletic Track Ground | E22: Kallankurichi Main Road, near Kallankurichi Bazaar, Ariyalur District, Tamil Nadu 621843 | F22: +91 99448 68733 | G22: Google Maps | H22: https://maps.google.com/?q=Vee+Kallankurichi+Athletic+Track+Ground+Ariyalur | I22: Tamil_Nadu_38_Districts_New_data.xlsx
... A106: 105 | B106: Ariyalur | C106: Cricket Turf | D106: Vee Silal Sports Turf | E106: Silal Main Road, near Silal Bazaar, Ariyalur District, Tamil Nadu 621729 | F106: +91 90035 92331 | G106: Google Maps | H106: https://maps.google.com/?q=Vee+Silal+Sports+Turf+Ariyalur | I106: Tamil_Nadu_38_Districts_New_data.xlsx
A107: 106 | B107: Ariyalur | C107: Cricket/Tennis/Basketball/Volleyball | D107: Devil Volleyball Ground | E107: Anna Nagar, Gandhi Nagar, Ariyalur-621704, Tamil Nadu | F107: closed | G107: 25/03/2026 | I107: TamilNadu_Sports_Data__1_.xlsx
A108: 107 | B108: Ariyalur | C108: Cricket/Tennis/Basketball/Volleyball | D108: Jk Cricket Academy | E108: No 235, Senthilnathan Hospital, Avs Box Cricket, TNHB Nagar, South, Ariyalur-621704, Tamil Nadu | F108: 7942684301 | G108: 25/03/2026 | I108: TamilNadu_Sports_Data__1_.xlsx
A109: 108 | B109: Ariyalur | C109: Cricket/Tennis/Basketball/Volleyball | D109: Yfi Cricket Ground | E109: Illuppaikudi, Yfi, Iluppaikudi, Ariyalur-621713, Tamil Nadu | G109: old data | I109: TamilNadu_Sports_Data__1_.xlsx
A110: 109 | B110: Ariyalur | C110: Cricket/Tennis/Hockey/Basketball/Volleyball | D110: FIELD HOCKEY GROUND | E110: 43WH+GGF SDAT sports complex, Kamarajar Nagar, Ariyalur, Tamil Nadu 621713 | F110: 74017 03499 | G110: 25/03/2026 | I110: TamilNadu_Sports_Data__1_.xlsx
A111: 110 | B111: Ariyalur | C111: Football Ground | D111: Apex Kulumur Football Ground | E111: Kulumur Main Road, near Kulumur Bazaar, Ariyalur District, Tamil Nadu 621794 | F111: +91 90035 33286 | G111: Google Maps | H111: https://maps.google.com/?q=Apex+Kulumur+Football+Ground+Ariyalur | I111: Tamil_Nadu_38_Districts_New_data.xlsx
A112: 111 | B112: Ariyalur | C112: Football Ground | D112: Ariyalur Sendurai Sports Field | E112: Sendurai Main Road, near Sendurai Bazaar, Ariyalur District, Tamil Nadu 621800 | F112: +91 94432 37345 | G112: Justdial | H112: https://maps.google.com/?q=Ariyalur+Sendurai+Sports+Field+Ariyalur | I112: Tamil_Nadu_38_Districts_New_data.xlsx
A113: 112 | B113: Ariyalur | C113: Football Ground | D113: Classic Vilandhai Football Ground | E113: Vilandhai Main Road, near Vilandhai Bazaar, Ariyalur District, Tamil Nadu 621793 | F113: +91 98421 49828 | G113: Google Maps | H113: https://maps.google.com/?q=Classic+Vilandhai+Football+Ground+Ariyalur | I113: Tamil_Nadu_38_Districts_New_data.xlsx
A114: 113 | B114: Ariyalur | C114: Football Ground | D114: District Keelapalur Sports Field | E114: Keelapalur Main Road, near Keelapalur Bazaar, Ariyalur District, Tamil Nadu 621815 | F114: +91 90035 52268 | G114: Justdial | H114: https://maps.google.com/?q=District+Keelapalur+Sports+Field+Ariyalur | I114: Tamil_Nadu_38_Districts_New_data.xlsx
A115: 114 | B115: Ariyalur | C115: Football Ground | D115: Dynamic Silal Sports Field | E115: Silal Main Road, near Silal Bazaar, Ariyalur District, Tamil Nadu 621807 | F115: +91 94432 21517 | G115: Google Maps | H115: https://maps.google.com/?q=Dynamic+Silal+Sports+Field+Ariyalur | I115: Tamil_Nadu_38_Districts_New_data.xlsx
A116: 115 | B116: Ariyalur | C116: Football Ground | D116: Dynamic Thirumanur Sports Field | E116: Thirumanur Main Road, near Thirumanur Bazaar, Ariyalur District, Tamil Nadu 621702 | F116: +91 97895 91595 | G116: Justdial | H116: https://maps.google.com/?q=Dynamic+Thirumanur+Sports+Field+Ariyalur | I116: Tamil_Nadu_38_Districts_New_data.xlsx
A117: 116 | B117: Ariyalur | C117: Football Ground | D117: Elite T. Palur Sports Field | E117: T. Palur Main Road, near T. Palur Bazaar, Ariyalur District, Tamil Nadu 621823 | F117: +91 96299 27409 | G117: Google Maps | H117: https://maps.google.com/?q=Elite+T.+Palur+Sports+Field+Ariyalur | I117: Tamil_Nadu_38_Districts_New_data.xlsx
A118: 117 | B118: Ariyalur | C118: Football Ground | D118: Global Thathanur Football Ground | E118: Thathanur Main Road, near Thathanur Bazaar, Ariyalur District, Tamil Nadu 621812 | F118: +91 96299 55293 | G118: Justdial | H118: https://maps.google.com/?q=Global+Thathanur+Football+Ground+Ariyalur | I118: Tamil_Nadu_38_Districts_New_data.xlsx
A119: 118 | B119: Ariyalur | C119: Football Ground | D119: Grand Andimadam Sports Field | E119: Andimadam Main Road, near Andimadam Bazaar, Ariyalur District, Tamil Nadu 621781 | F119: +91 98430 84678 | G119: Justdial | H119: https://maps.google.com/?q=Grand+Andimadam+Sports+Field+Ariyalur | I119: Tamil_Nadu_38_Districts_New_data.xlsx
A120: 119 | B120: Ariyalur | C120: Football Ground | D120: Marudhai Jayankondam Football Ground | E120: Jayankondam Main Road, near Jayankondam Bazaar, Ariyalur District, Tamil Nadu 621737 | F120: +91 90035 59381 | G120: Justdial | H120: https://maps.google.com/?q=Marudhai+Jayankondam+Football+Ground+Ariyalur | I120: Tamil_Nadu_38_Districts_New_data.xlsx
A121: 120 | B121: Ariyalur | C121: Football Ground | D121: Metro Elakurichi Sports Field | E121: Elakurichi Main Road, near Elakurichi Bazaar, Ariyalur District, Tamil Nadu 621838 | F121: +91 97895 67439 | G121: Justdial | H121: https://maps.google.com/?q=Metro+Elakurichi+Sports+Field+Ariyalur | I121: Tamil_Nadu_38_Districts_New_data.xlsx
A122: 121 | B122: Ariyalur | C122: Football Ground | D122: Prime T. Palur Football Ground | E122: T. Palur Main Road, near T. Palur Bazaar, Ariyalur District, Tamil Nadu 621711 | F122: +91 98421 62367 | G122: Google Maps | H122: https://maps.google.com/?q=Prime+T.+Palur+Football+Ground+Ariyalur | I122: Tamil_Nadu_38_Districts_New_data.xlsx
... A208: 207 | B208: Ariyalur | C208: Multi Sports Complex | D208: Titan Elakurichi Integrated Sports Arena | E208: Elakurichi Main Road, near Elakurichi Bazaar, Ariyalur District, Tamil Nadu 621779 | F208: +91 98430 87749 | G208: Google Maps | H208: https://maps.google.com/?q=Titan+Elakurichi+Integrated+Sports+Arena+Ariyalur | I208: Tamil_Nadu_38_Districts_New_data.xlsx
...

Sheet Chengalpattu
A1: S.No | B1: District | C1: Category | D1: Facility Name | E1: Address | F1: Phone | G1: Source | H1: Maps Link | I1: Origin File
A2: 1 | B2: Chengalpattu | C2: Academy | D2: Avalanche Badminton Academy | E2: Big Maniyakara St, 603001, Gokulapuram, Chengalpattu, Tamil Nadu 603002, Next Allahabad Bank), Gokulapuram, Chengalpattu-603001, Tamil Nadu | F2: 7942691095 | I2: TamilNadu_Sports_Data__1_.xlsx
A3: 2 | B3: Chengalpattu | C3: Academy | D3: CHENGALPATTU SPORTS ACADEMY | E3: MXGG+QP7, Anna Salai, Alagesan Nagar, Varadharaja Nagar, Chengalpattu, Ammanambakkam, Tamil Nadu 603001 | G3: 25/03/2026 | I3: TamilNadu_Sports_Data__1_.xlsx
A4: 3 | B4: Chengalpattu | C4: Academy | D4: Csk Badminton And Sports Academy Urapakkam | E4: Mayili Amman Kovil, 2ndstreet, Urapakkam, Karanai Puducherry Road, Guduvanchery, Chengalpattu-603202, Tamil Nadu | F4: 7947137656 | I4: TamilNadu_Sports_Data__1_.xlsx
A5: 4 | B5: Chengalpattu | C5: Academy | D5: Dev Sports Academy | E5: PX2C+CFQ, Kalathumettu street, J C K Nagar, Chengalpattu, Tamil Nadu 603002 | F5: 98423 28331 | G5: 25/03/2026 | I5: TamilNadu_Sports_Data__1_.xlsx
A6: 5 | B6: Chengalpattu | C6: Academy | D6: Dkayyes Batminton Academy | E6: No 37, Pankaja Ammal Nagar, Guduvanchery, Near Srm School, Madambakkam, Guduvanchery, Chengalpattu-603202, Tamil Nadu | F6: 7947426879 | I6: TamilNadu_Sports_Data__1_.xlsx
A7: 6 | B7: Chengalpattu | C7: Academy | D7: Dks Sports Academy | E7: R23G GH Maraimalai Nagar, Tamil Nadu, Valla MGR Salai, Opposite to ALWAR Palace, Maraimalai Nagar, Gandhi Road, Kattankolathur, Chengalpattu-603203, Tamil Nadu | F7: 7947124671 | G7: 25/03/2026 | I7: TamilNadu_Sports_Data__1_.xlsx
A8: 7 | B8: Chengalpattu | C8: Academy | D8: Dr. A P J Abdul Kalam Sports Academy | E8: No 5, Saratha Medical First Floor, Swamy Nagar, Railway Station Road, Urapakkam, Chengalpattu-603210, Tamil Nadu | F8: 7947138307 | G8: 25/03/2026 | I8: TamilNadu_Sports_Data__1_.xlsx
A9: 8 | B9: Chengalpattu | C9: Academy | D9: Dreamz Sports Academy | E9: Vishnu Priya Nagar, Near By Water Wash, Guduvanchery, Chengalpattu-603202, Tamil Nadu | F9: 7942690672 | G9: 25/03/2026 | I9: TamilNadu_Sports_Data__1_.xlsx
A10: 9 | B10: Chengalpattu | C10: Academy | D10: Indian Martial Arts Academy | E10: Near Kuppa Kariamman, Kuppa Kariamman Street, Singaperumalkoil, Chengalpattu-603204, Tamil Nadu | F10: 7942698814 | G10: 25/03/2026 | I10: TamilNadu_Sports_Data__1_.xlsx
A11: 10 | B11: Chengalpattu | C11: Academy | D11: Indian Martial Arts Academy ( IMAA) | E11: F.no 11/92, Near Padmasri Supermarket, Opposite to Ranga Bhavan, Kuppakari Amman Koil Street Thirutheri, Singaperumalkoil, Chengalpattu-603204, Tamil Nadu | F11: 7942691264 | G11: 25/03/2026 | I11: TamilNadu_Sports_Data__1_.xlsx
A12: 11 | B12: Chengalpattu | C12: Academy | D12: KJ Badminton Academy | E12: bus stop, Bajanai kovil street, near Nenmeli, Nenmeli, Chengalpattu, Tamil Nadu 603405 | F12: 90422 02855 | G12: 25/03/2026 | I12: TamilNadu_Sports_Data__1_.xlsx
A13: 12 | B13: Chengalpattu | C13: Academy | D13: Lotus Chess Academy | E13: 97/11, Near Prasanna Vidya Mandir, Big Maniyakara Street, Gokulapuram, Chengalpattu-603001, Tamil Nadu | F13: 7947417199 | G13: 25/03/2026 | I13: TamilNadu_Sports_Data__1_.xlsx
A14: 13 | B14: Chengalpattu | C14: Academy | D14: Master Badminton Academy | E14: Thenur, Sakthi Nagar, Chengalpattu-603001, Tamil Nadu | F14: 7947113763 | G14: 25/03/2026 | I14: TamilNadu_Sports_Data__1_.xlsx
A15: 14 | B15: Chengalpattu | C15: Academy | D15: Murali Badminton Academy | E15: No 59, Lakshmi Nagar, Near St Marys School, Nandhivaram, Nellikuppam Road, Guduvanchery, Chengalpattu-603202, Tamil Nadu | F15: 7947415252 | G15: 25/03/2026 | I15: TamilNadu_Sports_Data__1_.xlsx
A16: 15 | B16: Chengalpattu | C16: Academy | D16: NXT Gen Sports Academy | E16: No 43, Near to JRK Global School, Senthil Nagar, Chozhan Street, Kattankolathur, Chengalpattu-603203, Tamil Nadu | F16: closed | G16: old data | I16: TamilNadu_Sports_Data__1_.xlsx
A17: 16 | B17: Chengalpattu | C17: Academy | D17: Phoenix Martial Arts & Sports Academy | E17: Thiruvalluvar 3rd Street, Urapakkam, Chengalpattu-603210, Tamil Nadu | F17: 7947126361 | G17: 25/03/2026 | I17: TamilNadu_Sports_Data__1_.xlsx
A18: 17 | B18: Chengalpattu | C18: Academy | D18: Rajagopal Sports Academy | E18: Desumugi Pet, Tirukazhukundram, Tirukalikundram, Chengalpattu-603109, Tamil Nadu | F18: 7947117056 | G18: 25/03/2026 | I18: TamilNadu_Sports_Data__1_.xlsx
A19: 18 | B19: Chengalpattu | C19: Academy | D19: Rally Point Badminton Academy | E19: Teachers Colony, Nenmeli, Chengalpattu, Tamil Nadu 603003 | F19: 099622 08083 | G19: 25/03/2026 | I19: TamilNadu_Sports_Data__1_.xlsx
A20: 19 | B20: Chengalpattu | C20: Academy | D20: S V Sports Academy | E20: MXJC+PR9, Varadharaja Nagar, 3rd Main Rd, Hanumandhaputheri, Chengalpattu, Tamil Nadu 603002 | F20: 95000 40574 | G20: 25/03/2026 | I20: TamilNadu_Sports_Data__1_.xlsx
A21: 20 | B21: Chengalpattu | C21: Academy | D21: Soldiers sports academy ( FOOTBALL ⚽ ) AVIGNA BRANCH TURF | E21: P27H+V4F, MVM Nagar Road, MVM Nagar, Anjur R.F., Tamil Nadu 603002 | F21: 72-99-88-10-21 | G21: 25/03/2026 | I21: TamilNadu_Sports_Data__1_.xlsx
A22: 21 | B22: Chengalpattu | C22: Academy | D22: Spin & Smash Academy | E22: 59/1, Ramakrishna Nagar 1ststreet, Alapakkam, Chengalpattu, Tamil Nadu, Tkm Road, Amanambakkam, Chengalpattu-603003, Tamil Nadu | F22: 7947125629 | I22: TamilNadu_Sports_Data__1_.xlsx
A23: 22 | B23: Chengalpattu | C23: Academy | D23: Urapakkam Badminton Academy | E23: No 5, Avp Garden, Periyar Colony, Urapakkam, Near Holy Sai International School, Link Road, Adhanur, Chengalpattu-603202, Tamil Nadu | F23: 79474 34089 | G23: 25/03/2026 | I23: TamilNadu_Sports_Data__1_.xlsx
A24: 23 | B24: Chengalpattu | C24: Athletic Track | D24: Classic Maraimalai Nagar Athletic Track Ground | E24: Maraimalai Nagar Main Road, near Maraimalai Nagar Junction, Chengalpattu District, Tamil Nadu 603848 | F24: N/A | G24: Justdial | H24: https://maps.google.com/?q=Classic+Maraimalai+Nagar+Athletic+Track+Ground+Chengalpattu | I24: Tamil_Nadu_38_Districts_New_data.xlsx
A25: 24 | B25: Chengalpattu | C25: Athletic Track | D25: District Madurantakam Athletic Track Ground | E25: Madurantakam Main Road, near Madurantakam Junction, Chengalpattu District, Tamil Nadu 603715 | F25: +91 94432 74760 | G25: Google Maps | H25: https://maps.google.com/?q=District+Madurantakam+Athletic+Track+Ground+Chengalpattu | I25: Tamil_Nadu_38_Districts_New_data.xlsx
A26: 25 | B26: Chengalpattu | C26: Athletic Track | D26: Metro Nandivaram-Guduvancheri Running Stadium | E26: Nandivaram-Guduvancheri Main Road, near Nandivaram-Guduvancheri Junction, Chengalpattu District, Tamil Nadu 603711 | F26: N/A | G26: Google Maps | H26: https://maps.google.com/?q=Metro+Nandivaram-Guduvancheri+Running+Stadium+Chengalpattu | I26: Tamil_Nadu_38_Districts_New_data.xlsx
A27: 26 | B27: Chengalpattu | C27: Athletic Track | D27: Pallava Urapakkam Athletic Track Ground | E27: Urapakkam Main Road, near Urapakkam Junction, Chengalpattu District, Tamil Nadu 603841 | F27: +91 98430 68684 | G27: Google Maps | H27: https://maps.google.com/?q=Pallava+Urapakkam+Athletic+Track+Ground+Chengalpattu | I27: Tamil_Nadu_38_Districts_New_data.xlsx
A28: 27 | B28: Chengalpattu | C28: Athletic Track | D28: Pallavaram Guduvancheri Running Stadium | E28: Guduvancheri Main Road, near Guduvancheri Junction, Chengalpattu District, Tamil Nadu 603821 | F28: N/A | G28: Justdial | H28: https://maps.google.com/?q=Pallavaram+Guduvancheri+Running+Stadium+Chengalpattu | I28: Tamil_Nadu_38_Districts_New_data.xlsx
A29: 28 | B29: Chengalpattu | C29: Athletic Track | D29: Star Nandivaram-Guduvancheri Running Stadium | E29: Nandivaram-Guduvancheri Main Road, near Nandivaram-Guduvancheri Junction, Chengalpattu District, Tamil Nadu 603109 | F29: +91 98421 49646 | G29: Justdial | H29: https://maps.google.com/?q=Star+Nandivaram-Guduvancheri+Running+Stadium+Chengalpattu | I29: Tamil_Nadu_38_Districts_New_data.xlsx
A30: 29 | B30: Chengalpattu | C30: Athletic Track | D30: United Maraimalai Nagar Running Stadium | E30: Maraimalai Nagar Main Road, near Maraimalai Nagar Junction, Chengalpattu District, Tamil Nadu 603519 | F30: N/A | G30: Google Maps | H30: https://maps.google.com/?q=United+Maraimalai+Nagar+Running+Stadium+Chengalpattu | I30: Tamil_Nadu_38_Districts_New_data.xlsx
A31: 30 | B31: Chengalpattu | C31: Badminton Court | D31: Champion Thirukazhukundram Badminton Stadium | E31: Thirukazhukundram Main Road, near Thirukazhukundram Junction, Chengalpattu District, Tamil Nadu 604473 | F31: +91 98430 74612 | G31: Justdial | H31: https://maps.google.com/?q=Champion+Thirukazhukundram+Badminton+Stadium+Chengalpattu | I31: Tamil_Nadu_38_Districts_New_data.xlsx
A32: 31 | B32: Chengalpattu | C32: Badminton Court | D32: Chengalpattu Chromepet Badminton Club | E32: Chromepet Main Road, near Chromepet Junction, Chengalpattu District, Tamil Nadu 604072 | F32: +91 97500 31611 | G32: Justdial | H32: https://maps.google.com/?q=Chengalpattu+Chromepet+Badminton+Club+Chengalpattu | I32: Tamil_Nadu_38_Districts_New_data.xlsx
A33: 32 | B33: Chengalpattu | C33: Badminton Court | D33: Elite Nandivaram-Guduvancheri Badminton Stadium | E33: Nandivaram-Guduvancheri Main Road, near Nandivaram-Guduvancheri Junction, Chengalpattu District, Tamil Nadu 603655 | F33: +91 99448 32183 | G33: Justdial | H33: https://maps.google.com/?q=Elite+Nandivaram-Guduvancheri+Badminton+Stadium+Chengalpattu | I33: Tamil_Nadu_38_Districts_New_data.xlsx
A34: 33 | B34: Chengalpattu | C34: Badminton Court | D34: Elite Thiruporur Shuttle Badminton Arena | E34: Thiruporur Main Road, near Thiruporur Junction, Chengalpattu District, Tamil Nadu 603344 | F34: +91 97500 68645 | G34: Justdial | H34: https://maps.google.com/?q=Elite+Thiruporur+Shuttle+Badminton+Arena+Chengalpattu | I34: Tamil_Nadu_38_Districts_New_data.xlsx
A35: 34 | B35: Chengalpattu | C35: Badminton Court | D35: Metro Karunguzhi Badminton Club | E35: Karunguzhi Main Road, near Karunguzhi Junction, Chengalpattu District, Tamil Nadu 603815 | F35: +91 98430 50994 | G35: Justdial | H35: https://maps.google.com/?q=Metro+Karunguzhi+Badminton+Club+Chengalpattu | I35: Tamil_Nadu_38_Districts_New_data.xlsx
... A102: 101 | B102: Chengalpattu | C102: Cricket Turf | D102: Titan Kalpakkam Cricket Turf | E102: Kalpakkam Main Road, near Kalpakkam Junction, Chengalpattu District, Tamil Nadu 603638 | F102: +91 98421 73014 | G102: Justdial | H102: https://maps.google.com/?q=Titan+Kalpakkam+Cricket+Turf+Chengalpattu | I102: Tamil_Nadu_38_Districts_New_data.xlsx
A103: 102 | B103: Chengalpattu | C103: Cricket/Tennis/Hockey/Basketball/Volleyball | D103: SRM indoor badminton court | E103: Srm University, Kattankulathur, Tamil Nadu, Potheri, Chengalpattu-603203, Tamil Nadu | I103: TamilNadu_Sports_Data__1_.xlsx
A104: 103 | B104: Chengalpattu | C104: Football | D104: Avigna Football Ground | E104: P28G+2V3, Anjur R.F., Tamil Nadu 603002 | G104: 25/03/2026 | I104: TamilNadu_Sports_Data__1_.xlsx
A105: 104 | B105: Chengalpattu | C105: Football | D105: Bethel Nagar football Ground | E105: MXFX+VFC, Alapakkam, Chengalpattu, Tamil Nadu 603003 | G105: 25/03/2026 | I105: TamilNadu_Sports_Data__1_.xlsx
A106: 105 | B106: Chengalpattu | C106: Football | D106: CHN Infy Football Arena | E106: P2J4+HFC, Mahindra World City, Thirutheri R.F., Tamil Nadu 603004 | G106: 25/03/2026 | I106: TamilNadu_Sports_Data__1_.xlsx
...

Sheet Chennai
A1: S.No | B1: District | C1: Category | D1: Facility Name | E1: Address | F1: Phone | G1: Source | H1: Maps Link | I1: Origin File
A2: 1 | B2: Chennai | C2: Academy | D2: Aadukalam Sports Academy | E2: 42/1 Of 8, Below IOC Flyover, Vaidyanathan Street, Tondiarpet, Chennai-600081, Tamil Nadu | F2: 7947434243 | G2: 25/03/2026 | I2: TamilNadu_Sports_Data__1_.xlsx
A3: 2 | B3: Chennai | C3: Academy | D3: Aadukalam Sports Arena | E3: 48B, Mahaveer Street, Sathya Nagar, Padi, Chennai-600050, Tamil Nadu | F3: 7947147488 | G3: old data | I3: TamilNadu_Sports_Data__1_.xlsx
A4: 3 | B4: Chennai | C4: Academy | D4: Amr Football Academy | E4: No 2/2, Opposite to Srinivasa Kalyana Mandapam, Thulasingam Street, Oil Mill Road, Iyyappanthangal, Chennai-600056, Tamil Nadu | F4: 7947109067 | G4: old data | I4: TamilNadu_Sports_Data__1_.xlsx
A5: 4 | B5: Chennai | C5: Academy | D5: Berlin Sports Academy | E5: No 342/2, Opposite to Vallalar Department Store, Ganesh Nagar, Madhavaram, Chennai-600060, Tamil Nadu | F5: 7947110750 | G5: old data | I5: TamilNadu_Sports_Data__1_.xlsx
A6: 5 | B6: Chennai | C6: Academy | D6: Blaze Badminton Academy | E6: No 33, Vgp Rajesh Nagar, Narayanapuram, Rajesh Nagar 5th Main Road, Pallikaranai, Chennai-600100, Tamil Nadu | F6: 7947108788 | G6: 25/03/2026 | I6: TamilNadu_Sports_Data__1_.xlsx
A7: 6 | B7: Chennai | C7: Academy | D7: Chennai Strikers Football Academy | E7: No.456/1, 2ND MAIN ROAD, MADHAVARAM NEAR ST JOSEPH ACADEMY SCHOOL, GARDEN EXTENSION ROAD, 3RD CROSS ROAD, RING ROAD, MADHAVARAM, Madhavaram, Chennai-600060, Tamil Nadu | G7: old data | I7: TamilNadu_Sports_Data__1_.xlsx
A8: 7 | B8: Chennai | C8: Academy | D8: Dhoni Cricket Academy | E8: No 151E, Near Leo CBSE School, Pioneer Colony, E Main Road, Anna Nagar West Extension, Chennai-600101, Tamil Nadu | F8: 7947430419 | G8: old data | I8: TamilNadu_Sports_Data__1_.xlsx
A9: 8 | B9: Chennai | C9: Academy | D9: Dhoni Cricket Academy & Ground | E9: Near Csi Church, Mes Road, Tambaram, Chennai-600045, Tamil Nadu | F9: 098843 86974 | G9: old data | I9: TamilNadu_Sports_Data__1_.xlsx
A10: 9 | B10: Chennai | C10: Academy | D10: Dolphin Sports Academy | E10: 13, Near Ajay Stadium, Kovilpathagai Main Road, Avadi, Chennai-600054, Tamil Nadu | F10: 7947131838 | G10: 25/03/2026 | I10: TamilNadu_Sports_Data__1_.xlsx
A11: 10 | B11: Chennai | C11: Academy | D11: Dream Creation Badminton Academy | E11: No 47/36, Near By Best Hospital, Vellala Street, Kodambakkam, Chennai-600024, Tamil Nadu | F11: 9725134531 | G11: 25/03/2026 | I11: TamilNadu_Sports_Data__1_.xlsx
A12: 11 | B12: Chennai | C12: Academy | D12: Evolve Sports A' Wellness Academy | E12: 60a, Behind Velammal Vidyalaya, Kamachi Nagar, Sivabotham, Vanagaram, Chennai-600095, Tamil Nadu | F12: 8460232354 | G12: old data | I12: TamilNadu_Sports_Data__1_.xlsx
A13: 12 | B13: Chennai | C13: Academy | D13: Fitminton Badmiton Academy | E13: Fitminton Badminton Academy, 80, Near Sangeetha RA Puram, Kamarajar Salai, Raja Annamalai Puram, Chennai-600028, Tamil Nadu | F13: 7947435922 | G13: 25/03/2026 | I13: TamilNadu_Sports_Data__1_.xlsx
A14: 13 | B14: Chennai | C14: Academy | D14: G J Sports Academy | E14: No 1/36, Behind Pon Vidhya Ashramam School, Park Street Phase 1 Max Worth Nagar, Kolapakkam, Chennai-600048, Tamil Nadu | F14: 8296549583 | G14: 25/03/2026 | I14: TamilNadu_Sports_Data__1_.xlsx
A15: 14 | B15: Chennai | C15: Academy | D15: Gpd Cricket Ground | E15: New Gummidipoondi, Gummudipoondi, Gummidipundi, Chennai-601201, Tamil Nadu | G15: old data | I15: TamilNadu_Sports_Data__1_.xlsx
A16: 15 | B16: Chennai | C16: Academy | D16: JPS Sports Academy | E16: No 12, Behind Perumal Temple, Adhimulam Nagar Extn, Pallikaranai, Chennai-600100, Tamil Nadu | F16: 9740483570 | G16: 25/03/2026 | I16: TamilNadu_Sports_Data__1_.xlsx
A17: 16 | B17: Chennai | C17: Academy | D17: Jai Kasthuri Arranganadhan Sports Academy | E17: No 1, Near Baba Temple, Thillai Ganga Nagar 24th Street, Nanganallur, Chennai-600061, Tamil Nadu | F17: 07485901774 | G17: old data | I17: TamilNadu_Sports_Data__1_.xlsx
A18: 17 | B18: Chennai | C18: Academy | D18: K3 Academies | E18: Plot No 59, Bavani Amman Kovil Nearby, Bavani Amman Kovil Street, Ramakrishna Nagar, 1st Main Road, Velacheri, Chennai-600042, Tamil Nadu | F18: 8460510452 | G18: 25/03/2026 | I18: TamilNadu_Sports_Data__1_.xlsx
A19: 18 | B19: Chennai | C19: Academy | D19: Kinetic Sports Academy | E19: Kadapperi, Tambaram, Tiruneermalai Road, Tambaram, Chennai-600045, Tamil Nadu | F19: 8123528559 | G19: old data | I19: TamilNadu_Sports_Data__1_.xlsx
A20: 19 | B20: Chennai | C20: Academy | D20: Leap Sports Academy | E20: 268/11, Kazhipathur, Old Mahabalipuram Road, Kazhipattur, Chennai-603103, Tamil Nadu | F20: 07947420721 | G20: old data | I20: TamilNadu_Sports_Data__1_.xlsx
A21: 20 | B21: Chennai | C21: Academy | D21: Let's Play Badminton Academy | E21: No 173, Let\\\'s Play Badminton Academy, Near Gas Station, 14th Union Corbide Colony, 14th Union Corbide Colony Street Kodungaiyur, Kodungaiyur, Chennai-600118, Tamil Nadu | F21: 7795689200 | G21: 25/03/2026 | I21: TamilNadu_Sports_Data__1_.xlsx
A22: 21 | B22: Chennai | C22: Academy | D22: Love All Badminton Academy | E22: No 72, Ambattur Industrial Estate Road, Mogappair, Chennai-600037, Tamil Nadu | F22: 7947138586 | G22: 25/03/2026 | I22: TamilNadu_Sports_Data__1_.xlsx
A23: 22 | B23: Chennai | C23: Academy | D23: Lsn Sports Academy | E23: No 1, Near Rajeswari Super Market Eri Karai Road, Lakshmi Nagar 2nd Street Manavala Nagar Main Road, Sembakkam, Chennai-600073, Tamil Nadu | F23: 9710733189/9094913209/6369577133 | G23: 25/03/2026 | I23: TamilNadu_Sports_Data__1_.xlsx
A24: 23 | B24: Chennai | C24: Academy | D24: MCC Academy | E24: No.307A, Near Velammal School, Britania, Srinivasa Nagar Main Road, Kadirvedu, Surapet, Chennai-600062, Tamil Nadu | F24: 7947126800 | G24: old data | I24: TamilNadu_Sports_Data__1_.xlsx
A25: 24 | B25: Chennai | C25: Academy | D25: MCC Cricket Academy | E25: No 333, Ram Nagar South Extension, Behind 200 Feet Radial Road, Behind Aarna Mahal and Opposite A2B Bhavan, 13th Main Road, Pallikaranai, Chennai-600100, Tamil Nadu- | F25: 7947114748 | G25: old data | I25: TamilNadu_Sports_Data__1_.xlsx
A26: 25 | B26: Chennai | C26: Academy | D26: Madras Tekkerz Turf & Academy | E26: No 4, 123 A, Rajam Nagar, Anna Nagar, Sunnambu Kolathur Main Road, Kovilambakkam, Chennai-600129, Tamil Nadu | F26: 7942691440 | G26: old data | I26: TamilNadu_Sports_Data__1_.xlsx
A27: 26 | B27: Chennai | C27: Academy | D27: New Champions Cricket Academy | E27: No 495, Near YMCA Ground, Spice Ymca, Nandanam, Chennai-600035, Tamil Nadu | F27: 7947113028 | G27: old data | I27: TamilNadu_Sports_Data__1_.xlsx
A28: 27 | B28: Chennai | C28: Academy | D28: Next Level Cricket Academy | E28: 1, Brindharan Nagar, Ag\\\'s Colony, AGS Colony Extension-Thiruvanmiyur, Chennai-600041, Tamil Nadu | F28: 7942701060 | G28: old data | I28: TamilNadu_Sports_Data__1_.xlsx
A29: 28 | B29: Chennai | C29: Academy | D29: Nm Green Cricket Ground | E29: S8/1 Narayana Chetti Kulam, Near Navin Star Food, Mambakkam Main Road, Medavakkam, Chennai-600100, Tamil Nadu | F29: 086100 51003 | G29: old data | I29: TamilNadu_Sports_Data__1_.xlsx
A30: 29 | B30: Chennai | C30: Academy | D30: Outlast Football Academy | E30: 665, 2/3, Bajanai Kolli street, Devaraj Nagar, Sholinganallur, Chennai-600119, Tamil Nadu | F30: 7947411433 | G30: old data | I30: TamilNadu_Sports_Data__1_.xlsx
A31: 30 | B31: Chennai | C31: Academy | D31: Pluma Elite Badminton Academy | E31: No 115, Near Tharachand Nagar Park, Behind Balalok School, Saibaba Colony, Kaliammam Koil Street, Virugambakkam, Chennai-600092, Tamil Nadu | F31: 7942687301 | G31: 25/03/2026 | I31: TamilNadu_Sports_Data__1_.xlsx
A32: 31 | B32: Chennai | C32: Academy | D32: Ramji Cricket Academy (Rca) | E32: NEAR PONVIDHYASHRAM SCHOOL, Maxworth Nagar Phase 2, Kolapakkam, Chennai-600127, Tamil Nadu | F32: 7947141840 | G32: old data | I32: TamilNadu_Sports_Data__1_.xlsx
A33: 32 | B33: Chennai | C33: Academy | D33: SPR Sports Academy | E33: No 75, 1st Cross Street, Near Velu Pazhamuthir Nilayam, Sriram Nagar Main Road, Nolambur, Chennai-600037, Tamil Nadu | F33: 8971457420 | G33: old data | I33: TamilNadu_Sports_Data__1_.xlsx
A34: 33 | B34: Chennai | C34: Academy | D34: SPS Sports And Arts Academy | E34: No 1, SPS Sports and Arts Academy, Near VGN Stafford Appartments, Shanthi Nagar Extension, Golden Seetha Pandian Avenue, Tirumullaivayal, Chennai-600062, Tamil Nadu- | F34: 098415 48092 | G34: old data | I34: TamilNadu_Sports_Data__1_.xlsx
A35: 34 | B35: Chennai | C35: Academy | D35: Sling Shot Sports Academy | E35: No 60/28, Near Ponmani Maligai Or Shesya School, Bharateswarar Colony 3rd Street, Kodambakkam Power House, Kodambakkam, Chennai-600024, Tamil Nadu | F35: 7942684235 | G35: 25/03/2026 | I35: TamilNadu_Sports_Data__1_.xlsx
A36: 35 | B36: Chennai | C36: Academy | D36: Smasher 4.0 Sports Academy | E36: Plot No 1-6, Mangala Nagar, Sekkilar Street, Kavya Garden, 12th Cross Street, Mangla Nagar Extension, Porur, Chennai-600116, Tamil Nadu | F36: 090801 46461 | G36: old data | I36: TamilNadu_Sports_Data__1_.xlsx
A37: 36 | B37: Chennai | C37: Academy | D37: Stigmata Academy For Sports & Arts | E37: Wisdom Matriculation School, 2nd Floor Of, Sannathi Street, Kodungaiyur, Chennai - 600118, Tamil Nadu- | F37: 090800 28017,098400 68989,073585 23418 | G37: old data | I37: TamilNadu_Sports_Data__1_.xlsx
A38: 37 | B38: Chennai | C38: Academy | D38: Sun Shine Badminton Academy | E38: Plot No 85, Opposite Pink Fitness, AnnaSamy Street Vivekananda Nagar, Ramapuram, Chennai-600089, Tamil Nadu | F38: 095973 98638 | G38: 25/03/2026 | I38: TamilNadu_Sports_Data__1_.xlsx
A39: 38 | B39: Chennai | C39: Academy | D39: Tera sports academy | E39: No R1, Mathur, Ponniyamman Kovil Street, Manali, Chennai-600068, Tamil Nadu | F39: 095000 41569 | G39: old data | I39: TamilNadu_Sports_Data__1_.xlsx
A40: 39 | B40: Chennai | C40: Academy | D40: Trends Sports Academy | E40: No 57, VGP Selva Nagar, Behind Grand Mall, 1st Main Road, Velacheri, Chennai-600042, Tamil Nadu- | F40: 7947427365 | G40: 25/03/2026 | I40: TamilNadu_Sports_Data__1_.xlsx
...

Sheet Coimbatore
A1: S.No | B1: District | C1: Category | D1: Facility Name | E1: Address | F1: Phone | G1: Source | H1: Maps Link | I1: Origin File
A2: 1 | B2: Coimbatore | C2: Academy | D2: 5's crew football turf & academy | E2: chettiar thottam, 1/2, post, near canara bank, Badaga's Colony, K. Vadamadurai, Coimbatore, Kurudampalayam, Tamil Nadu 641017 | F2: 9047953552 | G2: 31/3/2026 | I2: TamilNadu_Sports_Data__1_.xlsx
A3: 2 | B3: Coimbatore | C3: Academy | D3: Bluemoon Sports Academy | E3: Near By Hundai Service Center, Balan Nagar, Kavundampalayam, Coimbatore-641030, Tamil Nadu | F3: 07904184152, 08220008849 | I3: TamilNadu_Sports_Data__1_.xlsx
A4: 3 | B4: Coimbatore | C4: Academy | D4: CC Football Academy | E4: SPN public school, bus stop, Mill Rd, near Marakkadai, Town Hall, Coimbatore, Tamil Nadu 641001 | F4: 9944977009 | G4: 31/3/2026 | I4: TamilNadu_Sports_Data__1_.xlsx
A5: 4 | B5: Coimbatore | C5: Academy | D5: Champ Badminton Academy | E5: 358 /2a, Sarojamani Nagar, Cheran Ma Nagar, Behind Sm Complex, Rethinam Nagar, Coimbatore-641035, Tamil Nadu | F5: 7947118613 | I5: TamilNadu_Sports_Data__1_.xlsx
A6: 5 | B6: Coimbatore | C6: Academy | D6: Champion Sports Academy | E6: Saraswathi Nagar, Mettupalayam Rd, behind Bharatham Palamuthir, Ajantha Nagar, Narasimhanaickenpalayam, Coimbatore, Tamil Nadu 641031 | F6: 9791657709 | G6: 31/3/2026 | I6: TamilNadu_Sports_Data__1_.xlsx
A7: 6 | B7: Coimbatore | C7: Academy | D7: Eagle Feathers | E7: 1/260, Siva Nagar, Government Press Employees Quarters, Press Colony, Press Colony, Coimbatore-641019, Tamil Nadu | F7: 7947134519 | I7: TamilNadu_Sports_Data__1_.xlsx
A8: 7 | B8: Coimbatore | C8: Academy | D8: Four Tora Badminton Academy | E8: Kurichi, Sundarapuram, Coimbatore-641024, Tamil Nadu | F8: 7947433022 | I8: TamilNadu_Sports_Data__1_.xlsx
A9: 8 | B9: Coimbatore | C9: Academy | D9: Game Point Badminton Academy | E9: #42, Near Ponnaiharajpuram Petrol Bunk, Opp. to Srivastava Rajguru Apartment, Chokkampudur Road, Ponnaiah Rajapuram, Coimbatore-641001, Tamil Nadu | F9: 9444700003 | I9: TamilNadu_Sports_Data__1_.xlsx
A10: 9 | B10: Coimbatore | C10: Academy | D10: Gamify Badminton Academy | E10: No. 93, Kongu Nagar, Gandhimaa Nagar, 10th Street, Ganapathi Maanagar, Coimbatore-641006, Tamil Nadu | F10: 7947431636 | I10: TamilNadu_Sports_Data__1_.xlsx
A11: 10 | B11: Coimbatore | C11: Academy | D11: Gg Soccer Academy | E11: No 717/1, 2a, Vadavalli Thonadamuthur Road, Opposite to Delhi Public School, Onappalayam, Coimbatore-641007, Tamil Nadu | F11: 7947144829 | G11: old data | I11: TamilNadu_Sports_Data__1_.xlsx
A12: 11 | B12: Coimbatore | C12: Academy | D12: Glowflow Tennis Academy | E12: Tiruppur, Minnagar, Coimbatore-641662, Tamil Nadu | G12: 30/3/2026 | I12: TamilNadu_Sports_Data__1_.xlsx
A13: 12 | B13: Coimbatore | C13: Academy | D13: Inspire Cricket Academy | E13: 13, Area 641, Area 641, Amman Kulam Road, Balasundaram Layout, Coimbatore-641044, Tamil Nadu | F13: 7947434512 | G13: old data | I13: TamilNadu_Sports_Data__1_.xlsx
A14: 13 | B14: Coimbatore | C14: Academy | D14: K G Ramesh Tennis Academy | E14: Guna Sports Complex, Thirumurugan Nagar, Coimbatore-641004, Tamil Nadu | F14: 7947413059 | G14: 30/3/2026 | I14: TamilNadu_Sports_Data__1_.xlsx
A15: 14 | B15: Coimbatore | C15: Academy | D15: KBR Sports & Art's Academy | E15: Opposite A1 Steel, Palladam to Coimbatore Road, Kalivellamapatti Pirivu East, Palladam, Palladam-641664, Tamil Nadu | F15: 8460505533 | G15: 29/03/2026 | I15: TamilNadu_Sports_Data__1_.xlsx
A16: 15 | B16: Coimbatore | C16: Academy | D16: Life Care Badminton Academy & Sports Complex | E16: No 99, Opposite Ruba Medical Care Hospital, Perur Main Road, Selvapuram, Coimbatore-641026, Tamil Nadu | F16: 7947420690 | G16: 30/3/2026 | I16: TamilNadu_Sports_Data__1_.xlsx
A17: 16 | B17: Coimbatore | C17: Academy | D17: May Flower Badminton Academy | E17: 21, Venkitasamy St, Sakthi Nagar, Koundampalayam, Edayarpalayam Koundampalayam Road, Kavundampalayam, Coimbatore-641030, Tamil Nadu | F17: 7947426829 | I17: TamilNadu_Sports_Data__1_.xlsx
A18: 17 | B18: Coimbatore | C18: Academy | D18: Maya Badminton Academy | E18: No 473/2f, Backside Sneha Hospital, Pkd Nagar, Peelamedu, Coimbatore-641004, Tamil Nadu | F18: 7947117996 | I18: TamilNadu_Sports_Data__1_.xlsx
A19: 18 | B19: Coimbatore | C19: Academy | D19: Mettupalayam Badminton Academy | E19: Sports Center, 207, Ponvizha Nagar Road, Mettupalayam, Coimbatore-641301, Tamil Nadu | F19: 7947131747 | I19: TamilNadu_Sports_Data__1_.xlsx
A20: 19 | B20: Coimbatore | C20: Academy | D20: Mohans Badminton Academy | E20: No 198, East Sambantham Road, RS Puram, Coimbatore-641002, Tamil Nadu | F20: 7942694529 | I20: TamilNadu_Sports_Data__1_.xlsx
A21: 20 | B21: Coimbatore | C21: Academy | D21: National Sports Academy | E21: Near Bharathiya Vidya Bhavan School, Ajjanoor, Vadavalli, Coimbatore-641041, Tamil Nadu | F21: 7942692052 | G21: 30/3/2026 | I21: TamilNadu_Sports_Data__1_.xlsx
A22: 21 | B22: Coimbatore | C22: Academy | D22: Neo Badminton Academy | E22: 360, Extension, Ganapathy, Karpaga Vinayagar Nagar, Coimbatore-641006, Tamil Nadu | F22: 9980239452 | I22: TamilNadu_Sports_Data__1_.xlsx
A23: 22 | B23: Coimbatore | C23: Academy | D23: Nilgiri Football Academy | E23: No.28, Pandiyans Industries Back Side, Rajiv Gandhi Road, Ganapathy, Coimbatore-641006, Tamil Nadu | F23: 7947128107 | G23: old data | I23: TamilNadu_Sports_Data__1_.xlsx
A24: 23 | B24: Coimbatore | C24: Academy | D24: PRABHUPRASANTH SPORTS MANAGEMENT | E24: PSGR Krishnammal College, Opposite to Fun Mall, Avinashi Road, Edayarpalayam, Coimbatore-641025, Tamil Nadu | F24: 7947417639 | I24: TamilNadu_Sports_Data__1_.xlsx
A25: 24 | B25: Coimbatore | C25: Academy | D25: Pink Badminton Academy | E25: Number 79, Opposite To Naven Weigh Bribge, Kovai Garden, Pachapalayam Perur, Coimbatore-641010, Tamil Nadu | F25: 7947148465 | I25: TamilNadu_Sports_Data__1_.xlsx
A26: 25 | B26: Coimbatore | C26: Academy | D26: Playpal Badminton | E26: Playpal, Saibaba Colony, Ramasamy Layout, Velandipalayam, Coimbatore-641025, Tamil Nadu | F26: 7947414571 | I26: TamilNadu_Sports_Data__1_.xlsx
A27: 26 | B27: Coimbatore | C27: Academy | D27: Premier Sports Academy | E27: No 538, Inside Sns Academy, Saravanampatti Thudiyalur Road, Vellakinar, Coimbatore-641029, Tamil Nadu | F27: 7947145552 | I27: TamilNadu_Sports_Data__1_.xlsx
A28: 27 | B28: Coimbatore | C28: Academy | D28: R V Badminton Academy | E28: No 643/2, Near Annapoorna Apartment, Vadavalli to Kanuvai Road, Vadavalli, Coimbatore-641041, Tamil Nadu | F28: 7947146119 | I28: TamilNadu_Sports_Data__1_.xlsx
A29: 28 | B29: Coimbatore | C29: Academy | D29: Rajesh Badminton Academy | E29: Rottikaran Thottam, Opposite to ESR Platinum Apartment, EB Colony, Edayarpalayam Road, Vadavalli, Coimbatore-641041, Tamil Nadu | F29: 8460542551 | I29: TamilNadu_Sports_Data__1_.xlsx
A30: 29 | B30: Coimbatore | C30: Academy | D30: Rv Sports Academy | E30: 2/182a, Norena Garden, Tamil Nadu, Coimbatore, Vadavalli, Coimbatore-641041, Tamil Nadu | F30: 097876 62663 | I30: TamilNadu_Sports_Data__1_.xlsx
A31: 30 | B31: Coimbatore | C31: Academy | D31: SR Sports Corp. | E31: Shri Nehru Vidhyalaya, PM Swamy Colony, RS Puram, Coimbatore-641002, Tamil Nadu | F31: 7947430830 | G31: old data | I31: TamilNadu_Sports_Data__1_.xlsx
A32: 31 | B32: Coimbatore | C32: Academy | D32: Sarah Sports Academy | E32: Kng Pudur Pirivu, Sri Saila Asaramam Temple, Thadagam Main Road, Kng Pudur Pirirvu, Coimbatore-641025, Tamil Nadu | F32: 7947417527 | G32: old data | I32: TamilNadu_Sports_Data__1_.xlsx
A33: 32 | B33: Coimbatore | C33: Academy | D33: Sizzlerss Badminton Academy | E33: 5/52 Vkl Nagar Road, Near Krishna Catering Service Hall, Near Krishna Catering Hall, Tudiyalur, Coimbatore, Thudialur, Coimbatore-641034, Tamil Nadu | F33: 7942692210 | I33: TamilNadu_Sports_Data__1_.xlsx
A34: 33 | B34: Coimbatore | C34: Academy | D34: Sk Badminton Academy | E34: Site No 9, Rramnagar, Post, P and T Colony, Koundampalayam, Tvs Nagar Koundampalayam Road, Kavundampalayam, Coimbatore-641030, Tamil Nadu | F34: 7947128750 | I34: TamilNadu_Sports_Data__1_.xlsx
A35: 34 | B35: Coimbatore | C35: Academy | D35: Sri Vinayaka Sports Academy | E35: Pattanam, Coimbatore-641016, Tamil Nadu | F35: 099760 66111 | I35: TamilNadu_Sports_Data__1_.xlsx
A36: 35 | B36: Coimbatore | C36: Academy | D36: St Batminton Academy | E36: No.5, Near RJ Matriculation School, Sree Garden, Vilankurichi, Coimbatore-641035, Tamil Nadu | F36: 7947134714 | I36: TamilNadu_Sports_Data__1_.xlsx
A37: 36 | B37: Coimbatore | C37: Academy | D37: Strikz Academy | E37: No 139/4b, Strikz Academy, Vellakinar Village, Thudiyalur -Saravanampatti Road, Vellakinar, Coimbatore-641029, Tamil Nadu | F37: 7942700984 | G37: old data | I37: TamilNadu_Sports_Data__1_.xlsx
A38: 37 | B38: Coimbatore | C38: Academy | D38: Suki Badminton Academy | E38: Chinmaya Nagar, Coimbatore, Veerakeralam, Coimbatore-641007, Tamil Nadu | I38: TamilNadu_Sports_Data__1_.xlsx
A39: 38 | B39: Coimbatore | C39: Academy | D39: Tamil Badminton Academy | E39: Surya Garden, Varri Garden, Tamil Nadu, Pannimadai, Coimbatore-641017, Tamil Nadu | F39: 7947430570 | I39: TamilNadu_Sports_Data__1_.xlsx
A40: 39 | B40: Coimbatore | C40: Academy | D40: The Tenniglo Academy | E40: Vilankurichi Road, Saravanampatti, Coimbatore-641035, Tamil Nadu | F40: 7947430278 | G40: 30/3/2026 | I40: TamilNadu_Sports_Data__1_.xlsx
...

Sheet Cuddalore
A1: S.No | B1: District | C1: Category | D1: Facility Name | E1: Address | F1: Phone | G1: Source | H1: Maps Link | I1: Origin File
A2: 1 | B2: Cuddalore | C2: Academy | D2: Anna Stadium | E2: QQ38+MG4, Avenue Road, Manjakuppam, Cuddalore, Tamil Nadu 607001 | F2: 4142220590 | G2: 31/3/2026 | I2: TamilNadu_Sports_Data__1_.xlsx
A3: 2 | B3: Cuddalore | C3: Academy | D3: Aréna31 Premium Badminton Club | E3: Beach Road, Rathinavel Nagar, Cuddalore, Tamil Nadu 607001 | F3: 9363630031 | G3: 31/3/2026 | I3: TamilNadu_Sports_Data__1_.xlsx
A4: 3 | B4: Cuddalore | C4: Academy | D4: Cuddalore Chess Academy | E4: Anna Stadium &, Seetharam Nagar, Pudupalayam, Cuddalore, Tamil Nadu 607001 | F4: 9087470774 | G4: 31/3/2026 | I4: TamilNadu_Sports_Data__1_.xlsx
A5: 4 | B5: Cuddalore | C5: Academy | D5: Jey Sports Academy | E5: Near Oasis School, Pudupalayam, Cuddalore-607001, Tamil Nadu | F5: 7947131670 | G5: 30/3/2026 | I5: TamilNadu_Sports_Data__1_.xlsx
A6: 5 | B6: Cuddalore | C6: Academy | D6: Mahaveer Badminton Academy | E6: 80, Sannathi St, Muthaiya Nagar, Thirupapuliyur, Cuddalore, Tamil Nadu 607002 | F6: 9787787787 | G6: 31/3/2026 | I6: TamilNadu_Sports_Data__1_.xlsx
A7: 6 | B7: Cuddalore | C7: Academy | D7: Mahaveerkids Badminton Academy | E7: 80, Sannathi St, Cuddalore, Thirupapuliyur, Cuddalore-607002, Tamil Nadu | F7: 7947122735 | I7: TamilNadu_Sports_Data__1_.xlsx
A8: 7 | B8: Cuddalore | C8: Academy | D8: NEXUS YOUTH SOCCER ACADEMY (NYSA) | E8: Anna stadium, Manjakuppam, Cuddalore, Tamil Nadu 607001 | F8: 094862 79797 | G8: 31/3/2026 | I8: TamilNadu_Sports_Data__1_.xlsx
A9: 8 | B9: Cuddalore | C9: Academy | D9: Royal Champion Shooting Sports Academy | E9: 6, Nellikuppam Main Rd, Pappammal Nagar, Vinayaga Nagar, Kondur, Tamil Nadu 607006 | F9: 9080180577 | G9: 31/3/2026 | I9: TamilNadu_Sports_Data__1_.xlsx
A10: 9 | B10: Cuddalore | C10: Academy | D10: SKB Badminton Academy | E10: No 5/4 ,MEDUTH STREET, S N CHAVADI, Thirupapuliyur, Cuddalore, Tamil Nadu 607002 | F10: 9443409411 | G10: 31/3/2026 | I10: TamilNadu_Sports_Data__1_.xlsx
A11: 10 | B11: Cuddalore | C11: Academy | D11: Sankaran Sports Academy | E11: 04, Mettustreet, Sn Chavadi, Thirupapuliyur, Cuddalore-607002, Tamil Nadu | F11: 7947110484 | G11: 31/3/2026 | I11: TamilNadu_Sports_Data__1_.xlsx
A12: 11 | B12: Cuddalore | C12: Academy | D12: Tiger International Institute of Martial Arts | E12: 28, Nethaji Rd, Allpettai, Manjakuppam, Cuddalore, Tamil Nadu 607001 | F12: 9361607001 | G12: 31/3/2026 | I12: TamilNadu_Sports_Data__1_.xlsx
A13: 12 | B13: Cuddalore | C13: Academy | D13: VSL BADMINTON ACADEMY | E13: 22A, V. S. L & Co No :326, 7, Nellikuppam Main Rd, Manjakuppam, Semmandalam, Tamil Nadu 607001 | G13: 31/3/2026 | I13: TamilNadu_Sports_Data__1_.xlsx
A14: 14 | B14: Cuddalore | C14: Academy | D14: Winners badminton club | E14: next to Ration shop, Anna Nagar, Cuddalore, Tamil Nadu 607001 | F14: 9894233028 | G14: 31/3/2026 | I14: TamilNadu_Sports_Data__1_.xlsx
A15: 15 | B15: Cuddalore | C15: Academy | D15: cuddalore skating | E15: No.1,annai illam, Nellikuppam Main Rd, Semmandalam, Tamil Nadu 607001 | G15: 31/3/2026 | I15: TamilNadu_Sports_Data__1_.xlsx
A16: 16 | B16: Cuddalore | C16: Athletic Track | D16: Champion Nellikuppam Running Stadium | E16: Nellikuppam Main Road, near Nellikuppam Bazaar, Cuddalore District, Tamil Nadu 607206 | F16: N/A | G16: Justdial | H16: https://maps.google.com/?q=Champion+Nellikuppam+Running+Stadium+Cuddalore | I16: Tamil_Nadu_38_Districts_New_data.xlsx
A17: 17 | B17: Cuddalore | C17: Athletic Track | D17: Cuddalore Parangipettai Running Stadium | E17: Parangipettai Main Road, near Parangipettai Bazaar, Cuddalore District, Tamil Nadu 607781 | F17: N/A | G17: Justdial | H17: https://maps.google.com/?q=Cuddalore+Parangipettai+Running+Stadium+Cuddalore | I17: Tamil_Nadu_38_Districts_New_data.xlsx
A18: 18 | B18: Cuddalore | C18: Athletic Track | D18: Elite Kattumannarkoil Athletic Track Ground | E18: Kattumannarkoil Main Road, near Kattumannarkoil Bazaar, Cuddalore District, Tamil Nadu 607941 | F18: +91 98430 78773 | G18: Google Maps | H18: https://maps.google.com/?q=Elite+Kattumannarkoil+Athletic+Track+Ground+Cuddalore | I18: Tamil_Nadu_38_Districts_New_data.xlsx
A19: 19 | B19: Cuddalore | C19: Athletic Track | D19: NLC Srimushnam Running Stadium | E19: Srimushnam Main Road, near Srimushnam Bazaar, Cuddalore District, Tamil Nadu 607517 | F19: +91 98421 13418 | G19: Justdial | H19: https://maps.google.com/?q=NLC+Srimushnam+Running+Stadium+Cuddalore | I19: Tamil_Nadu_38_Districts_New_data.xlsx
A20: 20 | B20: Cuddalore | C20: Athletic Track | D20: Prime Pennadam Athletic Track Ground | E20: Pennadam Main Road, near Pennadam Bazaar, Cuddalore District, Tamil Nadu 607376 | F20: +91 90035 47349 | G20: Google Maps | H20: https://maps.google.com/?q=Prime+Pennadam+Athletic+Track+Ground+Cuddalore | I20: Tamil_Nadu_38_Districts_New_data.xlsx
A21: 21 | B21: Cuddalore | C21: Athletic Track | D21: Prime Veppur Running Stadium | E21: Veppur Main Road, near Veppur Bazaar, Cuddalore District, Tamil Nadu 607946 | F21: +91 96299 75809 | G21: Justdial | H21: https://maps.google.com/?q=Prime+Veppur+Running+Stadium+Cuddalore | I21: Tamil_Nadu_38_Districts_New_data.xlsx
A22: 22 | B22: Cuddalore | C22: Athletic Track | D22: Pro Mangalampet Athletic Track Ground | E22: Mangalampet Main Road, near Mangalampet Bazaar, Cuddalore District, Tamil Nadu 607307 | F22: +91 99448 80805 | G22: Google Maps | H22: https://maps.google.com/?q=Pro+Mangalampet+Athletic+Track+Ground+Cuddalore | I22: Tamil_Nadu_38_Districts_New_data.xlsx
A23: 23 | B23: Cuddalore | C23: Badminton Court | D23: Apex Chidambaram Shuttle Badminton Arena | E23: Chidambaram Main Road, near Chidambaram Bazaar, Cuddalore District, Tamil Nadu 607527 | F23: +91 98421 16051 | G23: Justdial | H23: https://maps.google.com/?q=Apex+Chidambaram+Shuttle+Badminton+Arena+Cuddalore | I23: Tamil_Nadu_38_Districts_New_data.xlsx
A24: 24 | B24: Cuddalore | C24: Badminton Court | D24: Apex Kattumannarkoil Badminton Club | E24: Kattumannarkoil Main Road, near Kattumannarkoil Bazaar, Cuddalore District, Tamil Nadu 607585 | F24: +91 97500 80621 | G24: Justdial | H24: https://maps.google.com/?q=Apex+Kattumannarkoil+Badminton+Club+Cuddalore | I24: Tamil_Nadu_38_Districts_New_data.xlsx
A25: 25 | B25: Cuddalore | C25: Badminton Court | D25: Champion Pennadam Badminton Stadium | E25: Pennadam Main Road, near Pennadam Bazaar, Cuddalore District, Tamil Nadu 607209 | F25: +91 97500 85838 | G25: Google Maps | H25: https://maps.google.com/?q=Champion+Pennadam+Badminton+Stadium+Cuddalore | I25: Tamil_Nadu_38_Districts_New_data.xlsx
A26: 26 | B26: Cuddalore | C26: Badminton Court | D26: Chidambaram Indoor Badminton Stadium | E26: West Car Street, Chidambaram, Cuddalore District, Tamil Nadu 608001 | F26: +91 94435 22334 | G26: Google Maps | H26: https://maps.google.com/?q=Chidambaram+Indoor+Badminton+Stadium+Cuddalore | I26: Tamil_Nadu_38_Districts_New_data.xlsx
A27: 27 | B27: Cuddalore | C27: Badminton Court | D27: Dynamic Mangalampet Shuttle Badminton Arena | E27: Mangalampet Main Road, near Mangalampet Bazaar, Cuddalore District, Tamil Nadu 608048 | F27: +91 98421 49803 | G27: Google Maps | H27: https://maps.google.com/?q=Dynamic+Mangalampet+Shuttle+Badminton+Arena+Cuddalore | I27: Tamil_Nadu_38_Districts_New_data.xlsx
... A102: 102 | B102: Cuddalore | C102: Cricket Turf | D102: Virudhachalam Box Cricket Turf | E102: Salem Main Road, Virudhachalam, Cuddalore District, Tamil Nadu 606001 | F102: +91 98423 44556 | G102: Google Maps | H102: https://maps.google.com/?q=Virudhachalam+Box+Cricket+Turf+Cuddalore | I102: Tamil_Nadu_38_Districts_New_data.xlsx
A103: 103 | B103: Cuddalore | C103: Cricket/Tennis/Hockey/Basketball/Volleyball | D103: Cricket pitch | E103: Cricket Ground, QQ38+2F,Manjakuppam, Cuddalore-607001 | G103: 30/3/2026 | I103: TamilNadu_Sports_Data__1_.xlsx
A104: 104 | B104: Cuddalore | C104: Cricket/Tennis/Hockey/Basketball/Volleyball | D104: Cuddalore Lawn Tennis Association | E104: QQ38+79F, Avenue Road, Manjakuppam, Cuddalore, Tamil Nadu 607001 | G104: 31/3/2026 | I104: TamilNadu_Sports_Data__1_.xlsx
A105: 105 | B105: Cuddalore | C105: Cricket/Tennis/Hockey/Basketball/Volleyball | D105: Cuddalore Tennis Centre | E105: Near Pennaiyaru Bridge, Alwar Nagar, Alwar Nagar, Gundu Uppalavadi, Cuddalore-607006, Tamil Nadu | F105: 7947124884 | G105: 31/3/2026 | I105: TamilNadu_Sports_Data__1_.xlsx
A106: 106 | B106: Cuddalore | C106: Cricket/Tennis/Hockey/Basketball/Volleyball | D106: Cuddalore Tennis Centre & CTC Academy | E106: Alwar nagar, Periyakanganankuppam, Tamil Nadu 607006 | F106: 9952492098, | G106: 31/3/2026 | I106: TamilNadu_Sports_Data__1_.xlsx
A107: 107 | B107: Cuddalore | C107: Football | D107: Football pitch | E107: Football Ground ,QQ49+23F, Manjakuppam, Cuddalore-607001 | G107: old data | I107: TamilNadu_Sports_Data__1_.xlsx
A108: 108 | B108: Cuddalore | C108: Football Ground | D108: Apex Kumaratchi Football Ground | E108: Kumaratchi Main Road, near Kumaratchi Bazaar, Cuddalore District, Tamil Nadu 607357 | F108: +91 99448 38454 | G108: Justdial | H108: https://maps.google.com/?q=Apex+Kumaratchi+Football+Ground+Cuddalore | I108: Tamil_Nadu_38_Districts_New_data.xlsx
A109: 109 | B109: Cuddalore | C109: Football Ground | D109: Apex Neyveli Sports Field | E109: Neyveli Main Road, near Neyveli Bazaar, Cuddalore District, Tamil Nadu 607078 | F109: +91 97500 77355 | G109: Google Maps | H109: https://maps.google.com/?q=Apex+Neyveli+Sports+Field+Cuddalore | I109: Tamil_Nadu_38_Districts_New_data.xlsx
A110: 110 | B110: Cuddalore | C110: Football Ground | D110: Apex Tittagudi Football Ground | E110: Tittagudi Main Road, near Tittagudi Bazaar, Cuddalore District, Tamil Nadu 608045 | F110: +91 98421 65300 | G110: Google Maps | H110: https://maps.google.com/?q=Apex+Tittagudi+Football+Ground+Cuddalore | I110: Tamil_Nadu_38_Districts_New_data.xlsx
A111: 111 | B111: Cuddalore | C111: Football Ground | D111: Chidambaram Tittagudi Football Ground | E111: Tittagudi Main Road, near Tittagudi Bazaar, Cuddalore District, Tamil Nadu 608470 | F111: +91 90035 12659 | G111: Google Maps | H111: https://maps.google.com/?q=Chidambaram+Tittagudi+Football+Ground+Cuddalore | I111: Tamil_Nadu_38_Districts_New_data.xlsx
A112: 112 | B112: Cuddalore | C112: Football Ground | D112: Classic Veppur Sports Field | E112: Veppur Main Road, near Veppur Bazaar, Cuddalore District, Tamil Nadu 607844 | F112: +91 99448 65304 | G112: Google Maps | H112: https://maps.google.com/?q=Classic+Veppur+Sports+Field+Cuddalore | I112: Tamil_Nadu_38_Districts_New_data.xlsx
A113: 113 | B113: Cuddalore | C113: Football Ground | D113: Dynamic Sethiyathope Sports Field | E113: Sethiyathope Main Road, near Sethiyathope Bazaar, Cuddalore District, Tamil Nadu 607804 | F113: +91 98430 80904 | G113: Justdial | H113: https://maps.google.com/?q=Dynamic+Sethiyathope+Sports+Field+Cuddalore | I113: Tamil_Nadu_38_Districts_New_data.xlsx
A114: 114 | B114: Cuddalore | C114: Football Ground | D114: Global Killai Sports Field | E114: Killai Main Road, near Killai Bazaar, Cuddalore District, Tamil Nadu 607461 | F114: +91 97895 29254 | G114: Google Maps | H114: https://maps.google.com/?q=Global+Killai+Sports+Field+Cuddalore | I114: Tamil_Nadu_38_Districts_New_data.xlsx
...

Sheet Dharmapuri
A1: S.No | B1: District | C1: Category | D1: Facility Name | E1: Address | F1: Phone | G1: Source | H1: Maps Link | I1: Origin File
A2: 1 | B2: Dharmapuri | C2: Academy | D2: Dharmapuri Super Kings Cricket Academy | E2: Sri Venkateswara College Of Arts & Science, Sri Venkateswara College, Sogathur Post, Dharmapuri, Papinaickanahalli, Tamil Nadu 636809, India, Sogathur, Dharmapuri-636809, Tamil Nadu | F2: 7947114524 | G2: 31/3/2026 | I2: TamilNadu_Sports_Data__1_.xlsx
A3: 2 | B3: Dharmapuri | C3: Academy | D3: Nandhu sports academy | E3: R K. Hospital left building, Nethaji by pass road, Dharmapuri, Tamil Nadu 636701 | F3: 9842737016 | G3: 31/3/2026 | I3: TamilNadu_Sports_Data__1_.xlsx
A4: 3 | B4: Dharmapuri | C4: Academy | D4: R K Badminton Academy | E4: Indhira Nagar, Salem Main Road, Dharmapuri-636701, Tamil Nadu | F4: 9944256955 | I4: TamilNadu_Sports_Data__1_.xlsx
A5: 4 | B5: Dharmapuri | C5: Academy | D5: Rathinam Badminton Academy | E5: Thandu pathai annasagaram, way, Dharmapuri, Tamil Nadu 636701 | F5: 9944401762 | G5: 31/3/2026 | I5: TamilNadu_Sports_Data__1_.xlsx
A6: 5 | B6: Dharmapuri | C6: Academy | D6: Rathinam Sports & Tuvin Badminton Academy | E6: Thandu Pathai Annasagaram, Way, Annasagaram, Dharmapuri-636704, Tamil Nadu | F6: 7947148886 | G6: 31/3/2026 | I6: TamilNadu_Sports_Data__1_.xlsx
A7: 6 | B7: Dharmapuri | C7: Academy | D7: SK Cricket Academy | E7: Opp to Sri Amman Cars - Maruti Suzuki Showroom, Near Collector Bungalow, Adiyamankottai, Dharmapuri-636807, Tamil Nadu | F7: 7947419306 | G7: 31/3/2026 | I7: TamilNadu_Sports_Data__1_.xlsx
A8: 7 | B8: Dharmapuri | C8: Athletic Track | D8: Dynamic Laligam Athletic Track Ground | E8: Laligam Main Road, near Laligam Bazaar, Dharmapuri District, Tamil Nadu 636878 | F8: +91 99448 43249 | G8: Justdial | H8: https://maps.google.com/?q=Dynamic+Laligam+Athletic+Track+Ground+Dharmapuri | I8: Tamil_Nadu_38_Districts_New_data.xlsx
A9: 8 | B9: Dharmapuri | C9: Athletic Track | D9: Elite Vellichandai Running Stadium | E9: Vellichandai Main Road, near Vellichandai Bazaar, Dharmapuri District, Tamil Nadu 636831 | G9: Google Maps | H9: https://maps.google.com/?q=Elite+Vellichandai+Running+Stadium+Dharmapuri | I9: Tamil_Nadu_38_Districts_New_data.xlsx
A10: 9 | B10: Dharmapuri | C10: Athletic Track | D10: Morappur Harur Running Stadium | E10: Harur Main Road, near Harur Bazaar, Dharmapuri District, Tamil Nadu 636811 | F10: +91 94432 72310 | G10: Google Maps | H10: https://maps.google.com/?q=Morappur+Harur+Running+Stadium+Dharmapuri | I10: Tamil_Nadu_38_Districts_New_data.xlsx
